2024-11-19 15:46:58,029 [INFO] Starting Discord bot and web dashboard...
2024-11-19 15:46:58,031 [INFO] logging in using static token
2024-11-19 15:46:59,956 [CRITICAL] Critical error starting services: Improper token has been passed.
2024-11-19 15:47:20,368 [INFO] logging in using static token
2024-11-19 15:47:21,456 [ERROR] Error generating activity graph: No columns to parse from file
2024-11-19 15:47:21,471 [ERROR] Full traceback: Traceback (most recent call last):
  File "/home/kali/Desktop/bot/main2.py", line 256, in get_activity_graph
    df = pd.read_csv(log_file)
         ^^^^^^^^^^^^^^^^^^^^^
  File "/home/kali/Desktop/bot/venv/lib/python3.11/site-packages/pandas/io/parsers/readers.py", line 1026, in read_csv
    return _read(filepath_or_buffer, kwds)
           ^^^^^^^^^^^^^^^^^^^^^^^^^^^^^^^
  File "/home/kali/Desktop/bot/venv/lib/python3.11/site-packages/pandas/io/parsers/readers.py", line 620, in _read
    parser = TextFileReader(filepath_or_buffer, **kwds)
             ^^^^^^^^^^^^^^^^^^^^^^^^^^^^^^^^^^^^^^^^^^
  File "/home/kali/Desktop/bot/venv/lib/python3.11/site-packages/pandas/io/parsers/readers.py", line 1620, in __init__
    self._engine = self._make_engine(f, self.engine)
                   ^^^^^^^^^^^^^^^^^^^^^^^^^^^^^^^^^
  File "/home/kali/Desktop/bot/venv/lib/python3.11/site-packages/pandas/io/parsers/readers.py", line 1898, in _make_engine
    return mapping[engine](f, **self.options)
           ^^^^^^^^^^^^^^^^^^^^^^^^^^^^^^^^^^
  File "/home/kali/Desktop/bot/venv/lib/python3.11/site-packages/pandas/io/parsers/c_parser_wrapper.py", line 93, in __init__
    self._reader = parsers.TextReader(src, **kwds)
                   ^^^^^^^^^^^^^^^^^^^^^^^^^^^^^^^
  File "parsers.pyx", line 581, in pandas._libs.parsers.TextReader.__cinit__
pandas.errors.EmptyDataError: No columns to parse from file

2024-11-19 15:47:22,204 [ERROR] Error generating activity graph: No columns to parse from file
2024-11-19 15:47:22,206 [ERROR] Full traceback: Traceback (most recent call last):
  File "/home/kali/Desktop/bot/main2.py", line 256, in get_activity_graph
    df = pd.read_csv(log_file)
         ^^^^^^^^^^^^^^^^^^^^^
  File "/home/kali/Desktop/bot/venv/lib/python3.11/site-packages/pandas/io/parsers/readers.py", line 1026, in read_csv
    return _read(filepath_or_buffer, kwds)
           ^^^^^^^^^^^^^^^^^^^^^^^^^^^^^^^
  File "/home/kali/Desktop/bot/venv/lib/python3.11/site-packages/pandas/io/parsers/readers.py", line 620, in _read
    parser = TextFileReader(filepath_or_buffer, **kwds)
             ^^^^^^^^^^^^^^^^^^^^^^^^^^^^^^^^^^^^^^^^^^
  File "/home/kali/Desktop/bot/venv/lib/python3.11/site-packages/pandas/io/parsers/readers.py", line 1620, in __init__
    self._engine = self._make_engine(f, self.engine)
                   ^^^^^^^^^^^^^^^^^^^^^^^^^^^^^^^^^
  File "/home/kali/Desktop/bot/venv/lib/python3.11/site-packages/pandas/io/parsers/readers.py", line 1898, in _make_engine
    return mapping[engine](f, **self.options)
           ^^^^^^^^^^^^^^^^^^^^^^^^^^^^^^^^^^
  File "/home/kali/Desktop/bot/venv/lib/python3.11/site-packages/pandas/io/parsers/c_parser_wrapper.py", line 93, in __init__
    self._reader = parsers.TextReader(src, **kwds)
                   ^^^^^^^^^^^^^^^^^^^^^^^^^^^^^^^
  File "parsers.pyx", line 581, in pandas._libs.parsers.TextReader.__cinit__
pandas.errors.EmptyDataError: No columns to parse from file

2024-11-19 15:47:22,778 [ERROR] Error generating activity graph: No columns to parse from file
2024-11-19 15:47:22,779 [ERROR] Full traceback: Traceback (most recent call last):
  File "/home/kali/Desktop/bot/main2.py", line 256, in get_activity_graph
    df = pd.read_csv(log_file)
         ^^^^^^^^^^^^^^^^^^^^^
  File "/home/kali/Desktop/bot/venv/lib/python3.11/site-packages/pandas/io/parsers/readers.py", line 1026, in read_csv
    return _read(filepath_or_buffer, kwds)
           ^^^^^^^^^^^^^^^^^^^^^^^^^^^^^^^
  File "/home/kali/Desktop/bot/venv/lib/python3.11/site-packages/pandas/io/parsers/readers.py", line 620, in _read
    parser = TextFileReader(filepath_or_buffer, **kwds)
             ^^^^^^^^^^^^^^^^^^^^^^^^^^^^^^^^^^^^^^^^^^
  File "/home/kali/Desktop/bot/venv/lib/python3.11/site-packages/pandas/io/parsers/readers.py", line 1620, in __init__
    self._engine = self._make_engine(f, self.engine)
                   ^^^^^^^^^^^^^^^^^^^^^^^^^^^^^^^^^
  File "/home/kali/Desktop/bot/venv/lib/python3.11/site-packages/pandas/io/parsers/readers.py", line 1898, in _make_engine
    return mapping[engine](f, **self.options)
           ^^^^^^^^^^^^^^^^^^^^^^^^^^^^^^^^^^
  File "/home/kali/Desktop/bot/venv/lib/python3.11/site-packages/pandas/io/parsers/c_parser_wrapper.py", line 93, in __init__
    self._reader = parsers.TextReader(src, **kwds)
                   ^^^^^^^^^^^^^^^^^^^^^^^^^^^^^^^
  File "parsers.pyx", line 581, in pandas._libs.parsers.TextReader.__cinit__
pandas.errors.EmptyDataError: No columns to parse from file

2024-11-19 15:47:23,469 [ERROR] Error generating activity graph: No columns to parse from file
2024-11-19 15:47:23,471 [ERROR] Full traceback: Traceback (most recent call last):
  File "/home/kali/Desktop/bot/main2.py", line 256, in get_activity_graph
    df = pd.read_csv(log_file)
         ^^^^^^^^^^^^^^^^^^^^^
  File "/home/kali/Desktop/bot/venv/lib/python3.11/site-packages/pandas/io/parsers/readers.py", line 1026, in read_csv
    return _read(filepath_or_buffer, kwds)
           ^^^^^^^^^^^^^^^^^^^^^^^^^^^^^^^
  File "/home/kali/Desktop/bot/venv/lib/python3.11/site-packages/pandas/io/parsers/readers.py", line 620, in _read
    parser = TextFileReader(filepath_or_buffer, **kwds)
             ^^^^^^^^^^^^^^^^^^^^^^^^^^^^^^^^^^^^^^^^^^
  File "/home/kali/Desktop/bot/venv/lib/python3.11/site-packages/pandas/io/parsers/readers.py", line 1620, in __init__
    self._engine = self._make_engine(f, self.engine)
                   ^^^^^^^^^^^^^^^^^^^^^^^^^^^^^^^^^
  File "/home/kali/Desktop/bot/venv/lib/python3.11/site-packages/pandas/io/parsers/readers.py", line 1898, in _make_engine
    return mapping[engine](f, **self.options)
           ^^^^^^^^^^^^^^^^^^^^^^^^^^^^^^^^^^
  File "/home/kali/Desktop/bot/venv/lib/python3.11/site-packages/pandas/io/parsers/c_parser_wrapper.py", line 93, in __init__
    self._reader = parsers.TextReader(src, **kwds)
                   ^^^^^^^^^^^^^^^^^^^^^^^^^^^^^^^
  File "parsers.pyx", line 581, in pandas._libs.parsers.TextReader.__cinit__
pandas.errors.EmptyDataError: No columns to parse from file

2024-11-19 15:47:24,338 [ERROR] Error generating activity graph: No columns to parse from file
2024-11-19 15:47:24,340 [ERROR] Full traceback: Traceback (most recent call last):
  File "/home/kali/Desktop/bot/main2.py", line 256, in get_activity_graph
    df = pd.read_csv(log_file)
         ^^^^^^^^^^^^^^^^^^^^^
  File "/home/kali/Desktop/bot/venv/lib/python3.11/site-packages/pandas/io/parsers/readers.py", line 1026, in read_csv
    return _read(filepath_or_buffer, kwds)
           ^^^^^^^^^^^^^^^^^^^^^^^^^^^^^^^
  File "/home/kali/Desktop/bot/venv/lib/python3.11/site-packages/pandas/io/parsers/readers.py", line 620, in _read
    parser = TextFileReader(filepath_or_buffer, **kwds)
             ^^^^^^^^^^^^^^^^^^^^^^^^^^^^^^^^^^^^^^^^^^
  File "/home/kali/Desktop/bot/venv/lib/python3.11/site-packages/pandas/io/parsers/readers.py", line 1620, in __init__
    self._engine = self._make_engine(f, self.engine)
                   ^^^^^^^^^^^^^^^^^^^^^^^^^^^^^^^^^
  File "/home/kali/Desktop/bot/venv/lib/python3.11/site-packages/pandas/io/parsers/readers.py", line 1898, in _make_engine
    return mapping[engine](f, **self.options)
           ^^^^^^^^^^^^^^^^^^^^^^^^^^^^^^^^^^
  File "/home/kali/Desktop/bot/venv/lib/python3.11/site-packages/pandas/io/parsers/c_parser_wrapper.py", line 93, in __init__
    self._reader = parsers.TextReader(src, **kwds)
                   ^^^^^^^^^^^^^^^^^^^^^^^^^^^^^^^
  File "parsers.pyx", line 581, in pandas._libs.parsers.TextReader.__cinit__
pandas.errors.EmptyDataError: No columns to parse from file

2024-11-19 15:47:24,997 [ERROR] Error generating activity graph: No columns to parse from file
2024-11-19 15:47:24,999 [ERROR] Full traceback: Traceback (most recent call last):
  File "/home/kali/Desktop/bot/main2.py", line 256, in get_activity_graph
    df = pd.read_csv(log_file)
         ^^^^^^^^^^^^^^^^^^^^^
  File "/home/kali/Desktop/bot/venv/lib/python3.11/site-packages/pandas/io/parsers/readers.py", line 1026, in read_csv
    return _read(filepath_or_buffer, kwds)
           ^^^^^^^^^^^^^^^^^^^^^^^^^^^^^^^
  File "/home/kali/Desktop/bot/venv/lib/python3.11/site-packages/pandas/io/parsers/readers.py", line 620, in _read
    parser = TextFileReader(filepath_or_buffer, **kwds)
             ^^^^^^^^^^^^^^^^^^^^^^^^^^^^^^^^^^^^^^^^^^
  File "/home/kali/Desktop/bot/venv/lib/python3.11/site-packages/pandas/io/parsers/readers.py", line 1620, in __init__
    self._engine = self._make_engine(f, self.engine)
                   ^^^^^^^^^^^^^^^^^^^^^^^^^^^^^^^^^
  File "/home/kali/Desktop/bot/venv/lib/python3.11/site-packages/pandas/io/parsers/readers.py", line 1898, in _make_engine
    return mapping[engine](f, **self.options)
           ^^^^^^^^^^^^^^^^^^^^^^^^^^^^^^^^^^
  File "/home/kali/Desktop/bot/venv/lib/python3.11/site-packages/pandas/io/parsers/c_parser_wrapper.py", line 93, in __init__
    self._reader = parsers.TextReader(src, **kwds)
                   ^^^^^^^^^^^^^^^^^^^^^^^^^^^^^^^
  File "parsers.pyx", line 581, in pandas._libs.parsers.TextReader.__cinit__
pandas.errors.EmptyDataError: No columns to parse from file

2024-11-19 15:47:25,657 [ERROR] Error generating activity graph: No columns to parse from file
2024-11-19 15:47:25,659 [ERROR] Full traceback: Traceback (most recent call last):
  File "/home/kali/Desktop/bot/main2.py", line 256, in get_activity_graph
    df = pd.read_csv(log_file)
         ^^^^^^^^^^^^^^^^^^^^^
  File "/home/kali/Desktop/bot/venv/lib/python3.11/site-packages/pandas/io/parsers/readers.py", line 1026, in read_csv
    return _read(filepath_or_buffer, kwds)
           ^^^^^^^^^^^^^^^^^^^^^^^^^^^^^^^
  File "/home/kali/Desktop/bot/venv/lib/python3.11/site-packages/pandas/io/parsers/readers.py", line 620, in _read
    parser = TextFileReader(filepath_or_buffer, **kwds)
             ^^^^^^^^^^^^^^^^^^^^^^^^^^^^^^^^^^^^^^^^^^
  File "/home/kali/Desktop/bot/venv/lib/python3.11/site-packages/pandas/io/parsers/readers.py", line 1620, in __init__
    self._engine = self._make_engine(f, self.engine)
                   ^^^^^^^^^^^^^^^^^^^^^^^^^^^^^^^^^
  File "/home/kali/Desktop/bot/venv/lib/python3.11/site-packages/pandas/io/parsers/readers.py", line 1898, in _make_engine
    return mapping[engine](f, **self.options)
           ^^^^^^^^^^^^^^^^^^^^^^^^^^^^^^^^^^
  File "/home/kali/Desktop/bot/venv/lib/python3.11/site-packages/pandas/io/parsers/c_parser_wrapper.py", line 93, in __init__
    self._reader = parsers.TextReader(src, **kwds)
                   ^^^^^^^^^^^^^^^^^^^^^^^^^^^^^^^
  File "parsers.pyx", line 581, in pandas._libs.parsers.TextReader.__cinit__
pandas.errors.EmptyDataError: No columns to parse from file

2024-11-19 15:47:46,539 [INFO] logging in using static token
2024-11-19 15:47:47,406 [INFO] Sample timestamp from data: 2024-11-11 00:13:25.925926
2024-11-19 15:47:48,209 [INFO] Sample timestamp from data: 2024-11-11 00:13:25.925926
2024-11-19 15:47:48,313 [INFO] Sample timestamp from data: 2024-11-11 00:13:25.925926
2024-11-19 15:47:48,951 [INFO] Sample timestamp from data: 2024-11-11 00:13:25.925926
2024-11-19 15:47:49,672 [INFO] Sample timestamp from data: 2024-11-11 00:13:25.925926
2024-11-19 15:47:50,504 [INFO] Sample timestamp from data: 2024-11-11 00:13:25.925926
2024-11-19 15:47:51,415 [INFO] Sample timestamp from data: 2024-11-11 00:13:25.925926
2024-11-19 15:47:52,170 [INFO] Sample timestamp from data: 2024-11-11 00:13:25.925926
2024-11-19 15:47:53,166 [INFO] Sample timestamp from data: 2024-11-11 00:13:25.925926
2024-11-19 15:47:53,785 [INFO] Sample timestamp from data: 2024-11-11 00:13:25.925926
2024-11-19 15:47:54,476 [INFO] Sample timestamp from data: 2024-11-11 00:13:25.925926
2024-11-19 15:47:55,179 [INFO] Sample timestamp from data: 2024-11-11 00:13:25.925926
2024-11-19 15:47:55,869 [INFO] Sample timestamp from data: 2024-11-11 00:13:25.925926
2024-11-19 15:47:56,596 [INFO] Sample timestamp from data: 2024-11-11 00:13:25.925926
2024-11-19 15:47:57,433 [INFO] Sample timestamp from data: 2024-11-11 00:13:25.925926
2024-11-19 15:47:58,308 [INFO] Sample timestamp from data: 2024-11-11 00:13:25.925926
2024-11-19 15:47:58,984 [INFO] Sample timestamp from data: 2024-11-11 00:13:25.925926
2024-11-19 15:47:59,762 [INFO] Sample timestamp from data: 2024-11-11 00:13:25.925926
2024-11-19 15:48:00,628 [INFO] Sample timestamp from data: 2024-11-11 00:13:25.925926
2024-11-19 15:48:01,417 [INFO] Sample timestamp from data: 2024-11-11 00:13:25.925926
2024-11-19 15:48:02,264 [INFO] Sample timestamp from data: 2024-11-11 00:13:25.925926
2024-11-19 15:48:03,194 [INFO] Sample timestamp from data: 2024-11-11 00:13:25.925926
2024-11-19 15:48:04,118 [INFO] Sample timestamp from data: 2024-11-11 00:13:25.925926
2024-11-19 15:48:04,893 [INFO] Sample timestamp from data: 2024-11-11 00:13:25.925926
2024-11-19 15:48:05,862 [INFO] Sample timestamp from data: 2024-11-11 00:13:25.925926
2024-11-19 15:48:07,075 [INFO] Sample timestamp from data: 2024-11-11 00:13:25.925926
2024-11-19 15:48:08,100 [INFO] Sample timestamp from data: 2024-11-11 00:13:25.925926
2024-11-19 15:48:09,180 [INFO] Sample timestamp from data: 2024-11-11 00:13:25.925926
2024-11-19 15:48:10,493 [INFO] Sample timestamp from data: 2024-11-11 00:13:25.925926
2024-11-19 15:48:11,598 [INFO] Sample timestamp from data: 2024-11-11 00:13:25.925926
2024-11-19 15:48:12,460 [INFO] Sample timestamp from data: 2024-11-11 00:13:25.925926
2024-11-19 15:48:13,487 [INFO] Sample timestamp from data: 2024-11-11 00:13:25.925926
2024-11-19 15:48:15,035 [INFO] Sample timestamp from data: 2024-11-11 00:13:25.925926
2024-11-19 15:48:16,315 [INFO] Sample timestamp from data: 2024-11-11 00:13:25.925926
2024-11-19 15:48:18,113 [INFO] Sample timestamp from data: 2024-11-11 00:13:25.925926
2024-11-19 15:48:20,715 [INFO] Sample timestamp from data: 2024-11-11 00:13:25.925926
2024-11-19 15:48:21,829 [INFO] Sample timestamp from data: 2024-11-11 00:13:25.925926
2024-11-19 15:48:23,362 [INFO] Sample timestamp from data: 2024-11-11 00:13:25.925926
2024-11-19 15:48:24,856 [INFO] Sample timestamp from data: 2024-11-11 00:13:25.925926
2024-11-19 15:48:26,738 [INFO] Sample timestamp from data: 2024-11-11 00:13:25.925926
2024-11-19 15:49:30,933 [INFO] logging in using static token
2024-11-19 15:49:31,980 [INFO] Sample timestamp from data: 2024-11-11 00:13:25.925926
2024-11-19 15:49:32,664 [INFO] Sample timestamp from data: 2024-11-11 00:13:25.925926
2024-11-19 15:49:33,479 [INFO] Sample timestamp from data: 2024-11-11 00:13:25.925926
2024-11-19 15:49:34,321 [INFO] Sample timestamp from data: 2024-11-11 00:13:25.925926
2024-11-19 15:49:35,265 [INFO] Sample timestamp from data: 2024-11-11 00:13:25.925926
2024-11-19 15:49:36,321 [INFO] Sample timestamp from data: 2024-11-11 00:13:25.925926
2024-11-19 15:49:37,249 [INFO] Sample timestamp from data: 2024-11-11 00:13:25.925926
2024-11-19 15:49:38,180 [INFO] Sample timestamp from data: 2024-11-11 00:13:25.925926
2024-11-19 15:49:39,116 [INFO] Sample timestamp from data: 2024-11-11 00:13:25.925926
2024-11-19 15:52:20,141 [ERROR] Startup error: name 'run_fastapi' is not defined
2024-11-20 14:15:19,669 [INFO] logging in using static token
2024-11-20 14:15:21,822 [INFO] Bot initialized for guild: BeyondAI
2024-11-20 14:15:22,483 [INFO] Slash commands synced with Discord
2024-11-20 14:15:23,607 [INFO] Shard ID None has connected to Gateway (Session ID: 362f9cc1b441ee45dbfefe5a124e883c).
2024-11-20 14:15:25,710 [INFO] Bot is ready! Logged in as BeyondAI
2024-11-20 14:15:35,921 [ERROR] Error generating activity graph: time data "2024-11-11 04:22:11.966276" doesn't match format "%Y-%m-%dT%H:%M:%S.%f", at position 4. You might want to try:
    - passing `format` if your strings have a consistent format;
    - passing `format='ISO8601'` if your strings are all ISO8601 but not necessarily in exactly the same format;
    - passing `format='mixed'`, and the format will be inferred for each element individually. You might want to use `dayfirst` alongside this.
2024-11-20 14:15:37,135 [ERROR] Error generating activity graph: time data "2024-11-11 04:22:11.966276" doesn't match format "%Y-%m-%dT%H:%M:%S.%f", at position 4. You might want to try:
    - passing `format` if your strings have a consistent format;
    - passing `format='ISO8601'` if your strings are all ISO8601 but not necessarily in exactly the same format;
    - passing `format='mixed'`, and the format will be inferred for each element individually. You might want to use `dayfirst` alongside this.
2024-11-30 02:43:24,980 [WARNING] PyNaCl is not installed, voice will NOT be supported
2024-11-30 02:43:25,079 [INFO] logging in using static token
2024-11-30 02:43:26,806 [INFO] Bot initialized for guild: BeyondAI
2024-11-30 02:43:27,212 [INFO] Slash commands synced with Discord
2024-11-30 02:43:27,987 [INFO] Shard ID None has connected to Gateway (Session ID: b68d1cb574cc8262d8856429eb54aed1).
2024-11-30 02:43:30,022 [INFO] Bot is ready! Logged in as BeyondAI
2024-11-30 02:45:17,627 [ERROR] Error using Gemini API: 429 Quota exceeded for quota metric 'Generate Content API requests per minute' and limit 'GenerateContent request limit per minute for a region' of service 'generativelanguage.googleapis.com' for consumer 'project_number:790501917559'. [reason: "RATE_LIMIT_EXCEEDED"
domain: "googleapis.com"
metadata {
  key: "service"
  value: "generativelanguage.googleapis.com"
}
metadata {
  key: "quota_metric"
  value: "generativelanguage.googleapis.com/generate_content_requests"
}
metadata {
  key: "quota_location"
  value: "us-west4"
}
metadata {
  key: "quota_limit"
  value: "GenerateContentRequestsPerMinutePerProjectPerRegion"
}
metadata {
  key: "quota_limit_value"
  value: "0"
}
metadata {
  key: "consumer"
  value: "projects/790501917559"
}
, links {
  description: "Request a higher quota limit."
  url: "https://cloud.google.com/docs/quotas/help/request_increase"
}
]
2024-11-30 02:48:41,231 [WARNING] PyNaCl is not installed, voice will NOT be supported
2024-11-30 02:48:41,299 [INFO] logging in using static token
2024-11-30 02:48:42,995 [INFO] Bot initialized for guild: BeyondAI
2024-11-30 02:48:43,420 [INFO] Slash commands synced with Discord
2024-11-30 02:48:44,202 [INFO] Shard ID None has connected to Gateway (Session ID: 386693edaa2240566e6cafccc38b7da7).
2024-11-30 02:48:46,439 [INFO] Bot is ready! Logged in as BeyondAI
2024-11-30 02:49:20,682 [ERROR] Error using Gemini API: 404 Not Found (error code: 10062): Unknown interaction
2024-11-30 02:49:21,094 [ERROR] Ignoring exception in command 'api'
Traceback (most recent call last):
  File "d:\NEW\thinkingbeyond\bot\finalbot\finalwriteup.py", line 350, in api_command
    await interaction.response.defer()
  File "C:\Python312\Lib\site-packages\discord\interactions.py", line 709, in defer
    await adapter.create_interaction_response(
  File "C:\Python312\Lib\site-packages\discord\webhook\async_.py", line 221, in request
    raise NotFound(response, data)
discord.errors.NotFound: 404 Not Found (error code: 10062): Unknown interaction

During handling of the above exception, another exception occurred:

Traceback (most recent call last):
  File "C:\Python312\Lib\site-packages\discord\app_commands\commands.py", line 858, in _do_call
    return await self._callback(interaction, **params)  # type: ignore
           ^^^^^^^^^^^^^^^^^^^^^^^^^^^^^^^^^^^^^^^^^^^
  File "d:\NEW\thinkingbeyond\bot\finalbot\finalwriteup.py", line 371, in api_command
    await interaction.followup.send(error_msg)
  File "C:\Python312\Lib\site-packages\discord\webhook\async_.py", line 1843, in send
    data = await adapter.execute_webhook(
           ^^^^^^^^^^^^^^^^^^^^^^^^^^^^^^
  File "C:\Python312\Lib\site-packages\discord\webhook\async_.py", line 221, in request
    raise NotFound(response, data)
discord.errors.NotFound: 404 Not Found (error code: 10015): Unknown Webhook

The above exception was the direct cause of the following exception:

Traceback (most recent call last):
  File "C:\Python312\Lib\site-packages\discord\app_commands\tree.py", line 1310, in _call
    await command._invoke_with_namespace(interaction, namespace)
  File "C:\Python312\Lib\site-packages\discord\app_commands\commands.py", line 883, in _invoke_with_namespace
    return await self._do_call(interaction, transformed_values)
           ^^^^^^^^^^^^^^^^^^^^^^^^^^^^^^^^^^^^^^^^^^^^^^^^^^^^
  File "C:\Python312\Lib\site-packages\discord\app_commands\commands.py", line 876, in _do_call
    raise CommandInvokeError(self, e) from e
discord.app_commands.errors.CommandInvokeError: Command 'api' raised an exception: NotFound: 404 Not Found (error code: 10015): Unknown Webhook
2024-11-30 02:49:21,727 [ERROR] Error using Gemini API: 503 Service Unavailable (error code: 0): upstream connect error or disconnect/reset before headers. reset reason: connection timeout
2024-11-30 02:49:22,122 [ERROR] Ignoring exception in command 'api'
Traceback (most recent call last):
  File "d:\NEW\thinkingbeyond\bot\finalbot\finalwriteup.py", line 350, in api_command
    await interaction.response.defer()
  File "C:\Python312\Lib\site-packages\discord\interactions.py", line 709, in defer
    await adapter.create_interaction_response(
  File "C:\Python312\Lib\site-packages\discord\webhook\async_.py", line 233, in request
    raise DiscordServerError(response, data)
discord.errors.DiscordServerError: 503 Service Unavailable (error code: 0): upstream connect error or disconnect/reset before headers. reset reason: connection timeout

During handling of the above exception, another exception occurred:

Traceback (most recent call last):
  File "C:\Python312\Lib\site-packages\discord\app_commands\commands.py", line 858, in _do_call
    return await self._callback(interaction, **params)  # type: ignore
           ^^^^^^^^^^^^^^^^^^^^^^^^^^^^^^^^^^^^^^^^^^^
  File "d:\NEW\thinkingbeyond\bot\finalbot\finalwriteup.py", line 371, in api_command
    await interaction.followup.send(error_msg)
  File "C:\Python312\Lib\site-packages\discord\webhook\async_.py", line 1843, in send
    data = await adapter.execute_webhook(
           ^^^^^^^^^^^^^^^^^^^^^^^^^^^^^^
  File "C:\Python312\Lib\site-packages\discord\webhook\async_.py", line 221, in request
    raise NotFound(response, data)
discord.errors.NotFound: 404 Not Found (error code: 10015): Unknown Webhook

The above exception was the direct cause of the following exception:

Traceback (most recent call last):
  File "C:\Python312\Lib\site-packages\discord\app_commands\tree.py", line 1310, in _call
    await command._invoke_with_namespace(interaction, namespace)
  File "C:\Python312\Lib\site-packages\discord\app_commands\commands.py", line 883, in _invoke_with_namespace
    return await self._do_call(interaction, transformed_values)
           ^^^^^^^^^^^^^^^^^^^^^^^^^^^^^^^^^^^^^^^^^^^^^^^^^^^^
  File "C:\Python312\Lib\site-packages\discord\app_commands\commands.py", line 876, in _do_call
    raise CommandInvokeError(self, e) from e
discord.app_commands.errors.CommandInvokeError: Command 'api' raised an exception: NotFound: 404 Not Found (error code: 10015): Unknown Webhook
2024-11-30 04:58:53,718 [ERROR] Attempting a reconnect in 1.71s
Traceback (most recent call last):
  File "C:\Python312\Lib\site-packages\aiohttp\connector.py", line 1264, in _create_direct_connection
    hosts = await self._resolve_host(host, port, traces=traces)
            ^^^^^^^^^^^^^^^^^^^^^^^^^^^^^^^^^^^^^^^^^^^^^^^^^^^
  File "C:\Python312\Lib\site-packages\aiohttp\connector.py", line 890, in _resolve_host
    return await asyncio.shield(resolved_host_task)
           ^^^^^^^^^^^^^^^^^^^^^^^^^^^^^^^^^^^^^^^^
  File "C:\Python312\Lib\site-packages\aiohttp\connector.py", line 927, in _resolve_host_with_throttle
    addrs = await self._resolver.resolve(host, port, family=self._family)
            ^^^^^^^^^^^^^^^^^^^^^^^^^^^^^^^^^^^^^^^^^^^^^^^^^^^^^^^^^^^^^
  File "C:\Python312\Lib\site-packages\aiohttp\resolver.py", line 37, in resolve
    infos = await self._loop.getaddrinfo(
            ^^^^^^^^^^^^^^^^^^^^^^^^^^^^^
  File "C:\Python312\Lib\asyncio\base_events.py", line 899, in getaddrinfo
    return await self.run_in_executor(
           ^^^^^^^^^^^^^^^^^^^^^^^^^^^
  File "C:\Python312\Lib\concurrent\futures\thread.py", line 58, in run
    result = self.fn(*self.args, **self.kwargs)
             ^^^^^^^^^^^^^^^^^^^^^^^^^^^^^^^^^^
  File "C:\Python312\Lib\socket.py", line 963, in getaddrinfo
    for res in _socket.getaddrinfo(host, port, family, type, proto, flags):
               ^^^^^^^^^^^^^^^^^^^^^^^^^^^^^^^^^^^^^^^^^^^^^^^^^^^^^^^^^^^
socket.gaierror: [Errno 11001] getaddrinfo failed

The above exception was the direct cause of the following exception:

Traceback (most recent call last):
  File "C:\Python312\Lib\site-packages\discord\client.py", line 664, in connect
    self.ws = await asyncio.wait_for(coro, timeout=60.0)
              ^^^^^^^^^^^^^^^^^^^^^^^^^^^^^^^^^^^^^^^^^^
  File "C:\Python312\Lib\asyncio\tasks.py", line 520, in wait_for
    return await fut
           ^^^^^^^^^
  File "C:\Python312\Lib\site-packages\discord\gateway.py", line 374, in from_client
    socket = await client.http.ws_connect(str(url))
             ^^^^^^^^^^^^^^^^^^^^^^^^^^^^^^^^^^^^^^
  File "C:\Python312\Lib\site-packages\discord\http.py", line 550, in ws_connect
    return await self.__session.ws_connect(url, **kwargs)
           ^^^^^^^^^^^^^^^^^^^^^^^^^^^^^^^^^^^^^^^^^^^^^^
  File "C:\Python312\Lib\site-packages\aiohttp\client.py", line 922, in _ws_connect
    resp = await self.request(
           ^^^^^^^^^^^^^^^^^^^
  File "C:\Python312\Lib\site-packages\aiohttp\client.py", line 648, in _request
    conn = await self._connector.connect(
           ^^^^^^^^^^^^^^^^^^^^^^^^^^^^^^
  File "C:\Python312\Lib\site-packages\aiohttp\connector.py", line 546, in connect
    proto = await self._create_connection(req, traces, timeout)
            ^^^^^^^^^^^^^^^^^^^^^^^^^^^^^^^^^^^^^^^^^^^^^^^^^^^
  File "C:\Python312\Lib\site-packages\aiohttp\connector.py", line 954, in _create_connection
    _, proto = await self._create_direct_connection(req, traces, timeout)
               ^^^^^^^^^^^^^^^^^^^^^^^^^^^^^^^^^^^^^^^^^^^^^^^^^^^^^^^^^^
  File "C:\Python312\Lib\site-packages\aiohttp\connector.py", line 1270, in _create_direct_connection
    raise ClientConnectorError(req.connection_key, exc) from exc
aiohttp.client_exceptions.ClientConnectorError: Cannot connect to host gateway-us-east1-d.discord.gg:443 ssl:default [getaddrinfo failed]
2024-11-30 04:58:56,789 [ERROR] Attempting a reconnect in 1.14s
Traceback (most recent call last):
  File "C:\Python312\Lib\site-packages\aiohttp\connector.py", line 1264, in _create_direct_connection
    hosts = await self._resolve_host(host, port, traces=traces)
            ^^^^^^^^^^^^^^^^^^^^^^^^^^^^^^^^^^^^^^^^^^^^^^^^^^^
  File "C:\Python312\Lib\site-packages\aiohttp\connector.py", line 890, in _resolve_host
    return await asyncio.shield(resolved_host_task)
           ^^^^^^^^^^^^^^^^^^^^^^^^^^^^^^^^^^^^^^^^
  File "C:\Python312\Lib\site-packages\aiohttp\connector.py", line 927, in _resolve_host_with_throttle
    addrs = await self._resolver.resolve(host, port, family=self._family)
            ^^^^^^^^^^^^^^^^^^^^^^^^^^^^^^^^^^^^^^^^^^^^^^^^^^^^^^^^^^^^^
  File "C:\Python312\Lib\site-packages\aiohttp\resolver.py", line 37, in resolve
    infos = await self._loop.getaddrinfo(
            ^^^^^^^^^^^^^^^^^^^^^^^^^^^^^
  File "C:\Python312\Lib\asyncio\base_events.py", line 899, in getaddrinfo
    return await self.run_in_executor(
           ^^^^^^^^^^^^^^^^^^^^^^^^^^^
  File "C:\Python312\Lib\concurrent\futures\thread.py", line 58, in run
    result = self.fn(*self.args, **self.kwargs)
             ^^^^^^^^^^^^^^^^^^^^^^^^^^^^^^^^^^
  File "C:\Python312\Lib\socket.py", line 963, in getaddrinfo
    for res in _socket.getaddrinfo(host, port, family, type, proto, flags):
               ^^^^^^^^^^^^^^^^^^^^^^^^^^^^^^^^^^^^^^^^^^^^^^^^^^^^^^^^^^^
socket.gaierror: [Errno 11001] getaddrinfo failed

The above exception was the direct cause of the following exception:

Traceback (most recent call last):
  File "C:\Python312\Lib\site-packages\discord\client.py", line 664, in connect
    self.ws = await asyncio.wait_for(coro, timeout=60.0)
              ^^^^^^^^^^^^^^^^^^^^^^^^^^^^^^^^^^^^^^^^^^
  File "C:\Python312\Lib\asyncio\tasks.py", line 520, in wait_for
    return await fut
           ^^^^^^^^^
  File "C:\Python312\Lib\site-packages\discord\gateway.py", line 374, in from_client
    socket = await client.http.ws_connect(str(url))
             ^^^^^^^^^^^^^^^^^^^^^^^^^^^^^^^^^^^^^^
  File "C:\Python312\Lib\site-packages\discord\http.py", line 550, in ws_connect
    return await self.__session.ws_connect(url, **kwargs)
           ^^^^^^^^^^^^^^^^^^^^^^^^^^^^^^^^^^^^^^^^^^^^^^
  File "C:\Python312\Lib\site-packages\aiohttp\client.py", line 922, in _ws_connect
    resp = await self.request(
           ^^^^^^^^^^^^^^^^^^^
  File "C:\Python312\Lib\site-packages\aiohttp\client.py", line 648, in _request
    conn = await self._connector.connect(
           ^^^^^^^^^^^^^^^^^^^^^^^^^^^^^^
  File "C:\Python312\Lib\site-packages\aiohttp\connector.py", line 546, in connect
    proto = await self._create_connection(req, traces, timeout)
            ^^^^^^^^^^^^^^^^^^^^^^^^^^^^^^^^^^^^^^^^^^^^^^^^^^^
  File "C:\Python312\Lib\site-packages\aiohttp\connector.py", line 954, in _create_connection
    _, proto = await self._create_direct_connection(req, traces, timeout)
               ^^^^^^^^^^^^^^^^^^^^^^^^^^^^^^^^^^^^^^^^^^^^^^^^^^^^^^^^^^
  File "C:\Python312\Lib\site-packages\aiohttp\connector.py", line 1270, in _create_direct_connection
    raise ClientConnectorError(req.connection_key, exc) from exc
aiohttp.client_exceptions.ClientConnectorError: Cannot connect to host gateway-us-east1-d.discord.gg:443 ssl:default [getaddrinfo failed]
2024-11-30 04:58:57,959 [ERROR] Attempting a reconnect in 2.13s
Traceback (most recent call last):
  File "C:\Python312\Lib\site-packages\aiohttp\connector.py", line 1264, in _create_direct_connection
    hosts = await self._resolve_host(host, port, traces=traces)
            ^^^^^^^^^^^^^^^^^^^^^^^^^^^^^^^^^^^^^^^^^^^^^^^^^^^
  File "C:\Python312\Lib\site-packages\aiohttp\connector.py", line 890, in _resolve_host
    return await asyncio.shield(resolved_host_task)
           ^^^^^^^^^^^^^^^^^^^^^^^^^^^^^^^^^^^^^^^^
  File "C:\Python312\Lib\site-packages\aiohttp\connector.py", line 927, in _resolve_host_with_throttle
    addrs = await self._resolver.resolve(host, port, family=self._family)
            ^^^^^^^^^^^^^^^^^^^^^^^^^^^^^^^^^^^^^^^^^^^^^^^^^^^^^^^^^^^^^
  File "C:\Python312\Lib\site-packages\aiohttp\resolver.py", line 37, in resolve
    infos = await self._loop.getaddrinfo(
            ^^^^^^^^^^^^^^^^^^^^^^^^^^^^^
  File "C:\Python312\Lib\asyncio\base_events.py", line 899, in getaddrinfo
    return await self.run_in_executor(
           ^^^^^^^^^^^^^^^^^^^^^^^^^^^
  File "C:\Python312\Lib\concurrent\futures\thread.py", line 58, in run
    result = self.fn(*self.args, **self.kwargs)
             ^^^^^^^^^^^^^^^^^^^^^^^^^^^^^^^^^^
  File "C:\Python312\Lib\socket.py", line 963, in getaddrinfo
    for res in _socket.getaddrinfo(host, port, family, type, proto, flags):
               ^^^^^^^^^^^^^^^^^^^^^^^^^^^^^^^^^^^^^^^^^^^^^^^^^^^^^^^^^^^
socket.gaierror: [Errno 11001] getaddrinfo failed

The above exception was the direct cause of the following exception:

Traceback (most recent call last):
  File "C:\Python312\Lib\site-packages\discord\client.py", line 664, in connect
    self.ws = await asyncio.wait_for(coro, timeout=60.0)
              ^^^^^^^^^^^^^^^^^^^^^^^^^^^^^^^^^^^^^^^^^^
  File "C:\Python312\Lib\asyncio\tasks.py", line 520, in wait_for
    return await fut
           ^^^^^^^^^
  File "C:\Python312\Lib\site-packages\discord\gateway.py", line 374, in from_client
    socket = await client.http.ws_connect(str(url))
             ^^^^^^^^^^^^^^^^^^^^^^^^^^^^^^^^^^^^^^
  File "C:\Python312\Lib\site-packages\discord\http.py", line 550, in ws_connect
    return await self.__session.ws_connect(url, **kwargs)
           ^^^^^^^^^^^^^^^^^^^^^^^^^^^^^^^^^^^^^^^^^^^^^^
  File "C:\Python312\Lib\site-packages\aiohttp\client.py", line 922, in _ws_connect
    resp = await self.request(
           ^^^^^^^^^^^^^^^^^^^
  File "C:\Python312\Lib\site-packages\aiohttp\client.py", line 648, in _request
    conn = await self._connector.connect(
           ^^^^^^^^^^^^^^^^^^^^^^^^^^^^^^
  File "C:\Python312\Lib\site-packages\aiohttp\connector.py", line 546, in connect
    proto = await self._create_connection(req, traces, timeout)
            ^^^^^^^^^^^^^^^^^^^^^^^^^^^^^^^^^^^^^^^^^^^^^^^^^^^
  File "C:\Python312\Lib\site-packages\aiohttp\connector.py", line 954, in _create_connection
    _, proto = await self._create_direct_connection(req, traces, timeout)
               ^^^^^^^^^^^^^^^^^^^^^^^^^^^^^^^^^^^^^^^^^^^^^^^^^^^^^^^^^^
  File "C:\Python312\Lib\site-packages\aiohttp\connector.py", line 1270, in _create_direct_connection
    raise ClientConnectorError(req.connection_key, exc) from exc
aiohttp.client_exceptions.ClientConnectorError: Cannot connect to host gateway-us-east1-d.discord.gg:443 ssl:default [getaddrinfo failed]
2024-11-30 13:04:11,800 [ERROR] Attempting a reconnect in 0.01s
Traceback (most recent call last):
  File "C:\Python312\Lib\site-packages\aiohttp\connector.py", line 1264, in _create_direct_connection
    hosts = await self._resolve_host(host, port, traces=traces)
            ^^^^^^^^^^^^^^^^^^^^^^^^^^^^^^^^^^^^^^^^^^^^^^^^^^^
  File "C:\Python312\Lib\site-packages\aiohttp\connector.py", line 890, in _resolve_host
    return await asyncio.shield(resolved_host_task)
           ^^^^^^^^^^^^^^^^^^^^^^^^^^^^^^^^^^^^^^^^
  File "C:\Python312\Lib\site-packages\aiohttp\connector.py", line 927, in _resolve_host_with_throttle
    addrs = await self._resolver.resolve(host, port, family=self._family)
            ^^^^^^^^^^^^^^^^^^^^^^^^^^^^^^^^^^^^^^^^^^^^^^^^^^^^^^^^^^^^^
  File "C:\Python312\Lib\site-packages\aiohttp\resolver.py", line 37, in resolve
    infos = await self._loop.getaddrinfo(
            ^^^^^^^^^^^^^^^^^^^^^^^^^^^^^
  File "C:\Python312\Lib\asyncio\base_events.py", line 899, in getaddrinfo
    return await self.run_in_executor(
           ^^^^^^^^^^^^^^^^^^^^^^^^^^^
  File "C:\Python312\Lib\concurrent\futures\thread.py", line 58, in run
    result = self.fn(*self.args, **self.kwargs)
             ^^^^^^^^^^^^^^^^^^^^^^^^^^^^^^^^^^
  File "C:\Python312\Lib\socket.py", line 963, in getaddrinfo
    for res in _socket.getaddrinfo(host, port, family, type, proto, flags):
               ^^^^^^^^^^^^^^^^^^^^^^^^^^^^^^^^^^^^^^^^^^^^^^^^^^^^^^^^^^^
socket.gaierror: [Errno 11001] getaddrinfo failed

The above exception was the direct cause of the following exception:

Traceback (most recent call last):
  File "C:\Python312\Lib\site-packages\discord\client.py", line 664, in connect
    self.ws = await asyncio.wait_for(coro, timeout=60.0)
              ^^^^^^^^^^^^^^^^^^^^^^^^^^^^^^^^^^^^^^^^^^
  File "C:\Python312\Lib\asyncio\tasks.py", line 520, in wait_for
    return await fut
           ^^^^^^^^^
  File "C:\Python312\Lib\site-packages\discord\gateway.py", line 374, in from_client
    socket = await client.http.ws_connect(str(url))
             ^^^^^^^^^^^^^^^^^^^^^^^^^^^^^^^^^^^^^^
  File "C:\Python312\Lib\site-packages\discord\http.py", line 550, in ws_connect
    return await self.__session.ws_connect(url, **kwargs)
           ^^^^^^^^^^^^^^^^^^^^^^^^^^^^^^^^^^^^^^^^^^^^^^
  File "C:\Python312\Lib\site-packages\aiohttp\client.py", line 922, in _ws_connect
    resp = await self.request(
           ^^^^^^^^^^^^^^^^^^^
  File "C:\Python312\Lib\site-packages\aiohttp\client.py", line 648, in _request
    conn = await self._connector.connect(
           ^^^^^^^^^^^^^^^^^^^^^^^^^^^^^^
  File "C:\Python312\Lib\site-packages\aiohttp\connector.py", line 546, in connect
    proto = await self._create_connection(req, traces, timeout)
            ^^^^^^^^^^^^^^^^^^^^^^^^^^^^^^^^^^^^^^^^^^^^^^^^^^^
  File "C:\Python312\Lib\site-packages\aiohttp\connector.py", line 954, in _create_connection
    _, proto = await self._create_direct_connection(req, traces, timeout)
               ^^^^^^^^^^^^^^^^^^^^^^^^^^^^^^^^^^^^^^^^^^^^^^^^^^^^^^^^^^
  File "C:\Python312\Lib\site-packages\aiohttp\connector.py", line 1270, in _create_direct_connection
    raise ClientConnectorError(req.connection_key, exc) from exc
aiohttp.client_exceptions.ClientConnectorError: Cannot connect to host gateway-us-east1-d.discord.gg:443 ssl:default [getaddrinfo failed]
2024-11-30 13:04:11,825 [ERROR] Attempting a reconnect in 0.24s
Traceback (most recent call last):
  File "C:\Python312\Lib\site-packages\aiohttp\connector.py", line 1264, in _create_direct_connection
    hosts = await self._resolve_host(host, port, traces=traces)
            ^^^^^^^^^^^^^^^^^^^^^^^^^^^^^^^^^^^^^^^^^^^^^^^^^^^
  File "C:\Python312\Lib\site-packages\aiohttp\connector.py", line 890, in _resolve_host
    return await asyncio.shield(resolved_host_task)
           ^^^^^^^^^^^^^^^^^^^^^^^^^^^^^^^^^^^^^^^^
  File "C:\Python312\Lib\site-packages\aiohttp\connector.py", line 927, in _resolve_host_with_throttle
    addrs = await self._resolver.resolve(host, port, family=self._family)
            ^^^^^^^^^^^^^^^^^^^^^^^^^^^^^^^^^^^^^^^^^^^^^^^^^^^^^^^^^^^^^
  File "C:\Python312\Lib\site-packages\aiohttp\resolver.py", line 37, in resolve
    infos = await self._loop.getaddrinfo(
            ^^^^^^^^^^^^^^^^^^^^^^^^^^^^^
  File "C:\Python312\Lib\asyncio\base_events.py", line 899, in getaddrinfo
    return await self.run_in_executor(
           ^^^^^^^^^^^^^^^^^^^^^^^^^^^
  File "C:\Python312\Lib\concurrent\futures\thread.py", line 58, in run
    result = self.fn(*self.args, **self.kwargs)
             ^^^^^^^^^^^^^^^^^^^^^^^^^^^^^^^^^^
  File "C:\Python312\Lib\socket.py", line 963, in getaddrinfo
    for res in _socket.getaddrinfo(host, port, family, type, proto, flags):
               ^^^^^^^^^^^^^^^^^^^^^^^^^^^^^^^^^^^^^^^^^^^^^^^^^^^^^^^^^^^
socket.gaierror: [Errno 11001] getaddrinfo failed

The above exception was the direct cause of the following exception:

Traceback (most recent call last):
  File "C:\Python312\Lib\site-packages\discord\client.py", line 664, in connect
    self.ws = await asyncio.wait_for(coro, timeout=60.0)
              ^^^^^^^^^^^^^^^^^^^^^^^^^^^^^^^^^^^^^^^^^^
  File "C:\Python312\Lib\asyncio\tasks.py", line 520, in wait_for
    return await fut
           ^^^^^^^^^
  File "C:\Python312\Lib\site-packages\discord\gateway.py", line 374, in from_client
    socket = await client.http.ws_connect(str(url))
             ^^^^^^^^^^^^^^^^^^^^^^^^^^^^^^^^^^^^^^
  File "C:\Python312\Lib\site-packages\discord\http.py", line 550, in ws_connect
    return await self.__session.ws_connect(url, **kwargs)
           ^^^^^^^^^^^^^^^^^^^^^^^^^^^^^^^^^^^^^^^^^^^^^^
  File "C:\Python312\Lib\site-packages\aiohttp\client.py", line 922, in _ws_connect
    resp = await self.request(
           ^^^^^^^^^^^^^^^^^^^
  File "C:\Python312\Lib\site-packages\aiohttp\client.py", line 648, in _request
    conn = await self._connector.connect(
           ^^^^^^^^^^^^^^^^^^^^^^^^^^^^^^
  File "C:\Python312\Lib\site-packages\aiohttp\connector.py", line 546, in connect
    proto = await self._create_connection(req, traces, timeout)
            ^^^^^^^^^^^^^^^^^^^^^^^^^^^^^^^^^^^^^^^^^^^^^^^^^^^
  File "C:\Python312\Lib\site-packages\aiohttp\connector.py", line 954, in _create_connection
    _, proto = await self._create_direct_connection(req, traces, timeout)
               ^^^^^^^^^^^^^^^^^^^^^^^^^^^^^^^^^^^^^^^^^^^^^^^^^^^^^^^^^^
  File "C:\Python312\Lib\site-packages\aiohttp\connector.py", line 1270, in _create_direct_connection
    raise ClientConnectorError(req.connection_key, exc) from exc
aiohttp.client_exceptions.ClientConnectorError: Cannot connect to host gateway-us-east1-d.discord.gg:443 ssl:default [getaddrinfo failed]
2024-11-30 13:04:12,083 [ERROR] Attempting a reconnect in 5.43s
Traceback (most recent call last):
  File "C:\Python312\Lib\site-packages\aiohttp\connector.py", line 1264, in _create_direct_connection
    hosts = await self._resolve_host(host, port, traces=traces)
            ^^^^^^^^^^^^^^^^^^^^^^^^^^^^^^^^^^^^^^^^^^^^^^^^^^^
  File "C:\Python312\Lib\site-packages\aiohttp\connector.py", line 890, in _resolve_host
    return await asyncio.shield(resolved_host_task)
           ^^^^^^^^^^^^^^^^^^^^^^^^^^^^^^^^^^^^^^^^
  File "C:\Python312\Lib\site-packages\aiohttp\connector.py", line 927, in _resolve_host_with_throttle
    addrs = await self._resolver.resolve(host, port, family=self._family)
            ^^^^^^^^^^^^^^^^^^^^^^^^^^^^^^^^^^^^^^^^^^^^^^^^^^^^^^^^^^^^^
  File "C:\Python312\Lib\site-packages\aiohttp\resolver.py", line 37, in resolve
    infos = await self._loop.getaddrinfo(
            ^^^^^^^^^^^^^^^^^^^^^^^^^^^^^
  File "C:\Python312\Lib\asyncio\base_events.py", line 899, in getaddrinfo
    return await self.run_in_executor(
           ^^^^^^^^^^^^^^^^^^^^^^^^^^^
  File "C:\Python312\Lib\concurrent\futures\thread.py", line 58, in run
    result = self.fn(*self.args, **self.kwargs)
             ^^^^^^^^^^^^^^^^^^^^^^^^^^^^^^^^^^
  File "C:\Python312\Lib\socket.py", line 963, in getaddrinfo
    for res in _socket.getaddrinfo(host, port, family, type, proto, flags):
               ^^^^^^^^^^^^^^^^^^^^^^^^^^^^^^^^^^^^^^^^^^^^^^^^^^^^^^^^^^^
socket.gaierror: [Errno 11001] getaddrinfo failed

The above exception was the direct cause of the following exception:

Traceback (most recent call last):
  File "C:\Python312\Lib\site-packages\discord\client.py", line 664, in connect
    self.ws = await asyncio.wait_for(coro, timeout=60.0)
              ^^^^^^^^^^^^^^^^^^^^^^^^^^^^^^^^^^^^^^^^^^
  File "C:\Python312\Lib\asyncio\tasks.py", line 520, in wait_for
    return await fut
           ^^^^^^^^^
  File "C:\Python312\Lib\site-packages\discord\gateway.py", line 374, in from_client
    socket = await client.http.ws_connect(str(url))
             ^^^^^^^^^^^^^^^^^^^^^^^^^^^^^^^^^^^^^^
  File "C:\Python312\Lib\site-packages\discord\http.py", line 550, in ws_connect
    return await self.__session.ws_connect(url, **kwargs)
           ^^^^^^^^^^^^^^^^^^^^^^^^^^^^^^^^^^^^^^^^^^^^^^
  File "C:\Python312\Lib\site-packages\aiohttp\client.py", line 922, in _ws_connect
    resp = await self.request(
           ^^^^^^^^^^^^^^^^^^^
  File "C:\Python312\Lib\site-packages\aiohttp\client.py", line 648, in _request
    conn = await self._connector.connect(
           ^^^^^^^^^^^^^^^^^^^^^^^^^^^^^^
  File "C:\Python312\Lib\site-packages\aiohttp\connector.py", line 546, in connect
    proto = await self._create_connection(req, traces, timeout)
            ^^^^^^^^^^^^^^^^^^^^^^^^^^^^^^^^^^^^^^^^^^^^^^^^^^^
  File "C:\Python312\Lib\site-packages\aiohttp\connector.py", line 954, in _create_connection
    _, proto = await self._create_direct_connection(req, traces, timeout)
               ^^^^^^^^^^^^^^^^^^^^^^^^^^^^^^^^^^^^^^^^^^^^^^^^^^^^^^^^^^
  File "C:\Python312\Lib\site-packages\aiohttp\connector.py", line 1270, in _create_direct_connection
    raise ClientConnectorError(req.connection_key, exc) from exc
aiohttp.client_exceptions.ClientConnectorError: Cannot connect to host gateway-us-east1-d.discord.gg:443 ssl:default [getaddrinfo failed]
2024-11-30 13:04:18,243 [INFO] Shard ID None session has been invalidated.
2024-11-30 14:31:03,160 [WARNING] Shard ID None has stopped responding to the gateway. Closing and restarting.
2024-11-30 14:31:04,180 [INFO] Shard ID None session has been invalidated.
2024-11-30 14:31:10,619 [INFO] Shard ID None has connected to Gateway (Session ID: c76b6d1998f4e34a2a706c6aef1d8ad2).
2024-11-30 14:31:12,793 [INFO] Bot is ready! Logged in as BeyondAI
2024-11-30 14:31:21,277 [ERROR] Error using Gemini API: 429 Quota exceeded for quota metric 'Generate Content API requests per minute' and limit 'GenerateContent request limit per minute for a region' of service 'generativelanguage.googleapis.com' for consumer 'project_number:790501917559'. [reason: "RATE_LIMIT_EXCEEDED"
domain: "googleapis.com"
metadata {
  key: "service"
  value: "generativelanguage.googleapis.com"
}
metadata {
  key: "quota_metric"
  value: "generativelanguage.googleapis.com/generate_content_requests"
}
metadata {
  key: "quota_location"
  value: "us-west4"
}
metadata {
  key: "quota_limit"
  value: "GenerateContentRequestsPerMinutePerProjectPerRegion"
}
metadata {
  key: "quota_limit_value"
  value: "0"
}
metadata {
  key: "consumer"
  value: "projects/790501917559"
}
, links {
  description: "Request a higher quota limit."
  url: "https://cloud.google.com/docs/quotas/help/request_increase"
}
]
2024-11-30 14:39:55,556 [WARNING] PyNaCl is not installed, voice will NOT be supported
2024-11-30 14:39:55,660 [INFO] logging in using static token
2024-11-30 14:39:57,316 [INFO] Bot initialized for guild: BeyondAI
2024-11-30 14:39:57,712 [INFO] Slash commands synced with Discord
2024-11-30 14:39:58,450 [INFO] Shard ID None has connected to Gateway (Session ID: 385c5942a04fb32c1e5874aab8750ecc).
2024-11-30 14:40:00,483 [INFO] Bot is ready! Logged in as BeyondAI
2024-11-30 14:40:06,896 [ERROR] Error using Gemini API: 429 Quota exceeded for quota metric 'Generate Content API requests per minute' and limit 'GenerateContent request limit per minute for a region' of service 'generativelanguage.googleapis.com' for consumer 'project_number:790501917559'. [reason: "RATE_LIMIT_EXCEEDED"
domain: "googleapis.com"
metadata {
  key: "service"
  value: "generativelanguage.googleapis.com"
}
metadata {
  key: "quota_metric"
  value: "generativelanguage.googleapis.com/generate_content_requests"
}
metadata {
  key: "quota_location"
  value: "us-west4"
}
metadata {
  key: "quota_limit"
  value: "GenerateContentRequestsPerMinutePerProjectPerRegion"
}
metadata {
  key: "quota_limit_value"
  value: "0"
}
metadata {
  key: "consumer"
  value: "projects/790501917559"
}
, links {
  description: "Request a higher quota limit."
  url: "https://cloud.google.com/docs/quotas/help/request_increase"
}
]
2024-11-30 14:50:17,549 [ERROR] Attempting a reconnect in 0.62s
Traceback (most recent call last):
  File "C:\Python312\Lib\site-packages\aiohttp\connector.py", line 1264, in _create_direct_connection
    hosts = await self._resolve_host(host, port, traces=traces)
            ^^^^^^^^^^^^^^^^^^^^^^^^^^^^^^^^^^^^^^^^^^^^^^^^^^^
  File "C:\Python312\Lib\site-packages\aiohttp\connector.py", line 890, in _resolve_host
    return await asyncio.shield(resolved_host_task)
           ^^^^^^^^^^^^^^^^^^^^^^^^^^^^^^^^^^^^^^^^
  File "C:\Python312\Lib\site-packages\aiohttp\connector.py", line 927, in _resolve_host_with_throttle
    addrs = await self._resolver.resolve(host, port, family=self._family)
            ^^^^^^^^^^^^^^^^^^^^^^^^^^^^^^^^^^^^^^^^^^^^^^^^^^^^^^^^^^^^^
  File "C:\Python312\Lib\site-packages\aiohttp\resolver.py", line 37, in resolve
    infos = await self._loop.getaddrinfo(
            ^^^^^^^^^^^^^^^^^^^^^^^^^^^^^
  File "C:\Python312\Lib\asyncio\base_events.py", line 899, in getaddrinfo
    return await self.run_in_executor(
           ^^^^^^^^^^^^^^^^^^^^^^^^^^^
  File "C:\Python312\Lib\concurrent\futures\thread.py", line 58, in run
    result = self.fn(*self.args, **self.kwargs)
             ^^^^^^^^^^^^^^^^^^^^^^^^^^^^^^^^^^
  File "C:\Python312\Lib\socket.py", line 963, in getaddrinfo
    for res in _socket.getaddrinfo(host, port, family, type, proto, flags):
               ^^^^^^^^^^^^^^^^^^^^^^^^^^^^^^^^^^^^^^^^^^^^^^^^^^^^^^^^^^^
socket.gaierror: [Errno 11001] getaddrinfo failed

The above exception was the direct cause of the following exception:

Traceback (most recent call last):
  File "C:\Python312\Lib\site-packages\discord\client.py", line 664, in connect
    self.ws = await asyncio.wait_for(coro, timeout=60.0)
              ^^^^^^^^^^^^^^^^^^^^^^^^^^^^^^^^^^^^^^^^^^
  File "C:\Python312\Lib\asyncio\tasks.py", line 520, in wait_for
    return await fut
           ^^^^^^^^^
  File "C:\Python312\Lib\site-packages\discord\gateway.py", line 374, in from_client
    socket = await client.http.ws_connect(str(url))
             ^^^^^^^^^^^^^^^^^^^^^^^^^^^^^^^^^^^^^^
  File "C:\Python312\Lib\site-packages\discord\http.py", line 550, in ws_connect
    return await self.__session.ws_connect(url, **kwargs)
           ^^^^^^^^^^^^^^^^^^^^^^^^^^^^^^^^^^^^^^^^^^^^^^
  File "C:\Python312\Lib\site-packages\aiohttp\client.py", line 922, in _ws_connect
    resp = await self.request(
           ^^^^^^^^^^^^^^^^^^^
  File "C:\Python312\Lib\site-packages\aiohttp\client.py", line 648, in _request
    conn = await self._connector.connect(
           ^^^^^^^^^^^^^^^^^^^^^^^^^^^^^^
  File "C:\Python312\Lib\site-packages\aiohttp\connector.py", line 546, in connect
    proto = await self._create_connection(req, traces, timeout)
            ^^^^^^^^^^^^^^^^^^^^^^^^^^^^^^^^^^^^^^^^^^^^^^^^^^^
  File "C:\Python312\Lib\site-packages\aiohttp\connector.py", line 954, in _create_connection
    _, proto = await self._create_direct_connection(req, traces, timeout)
               ^^^^^^^^^^^^^^^^^^^^^^^^^^^^^^^^^^^^^^^^^^^^^^^^^^^^^^^^^^
  File "C:\Python312\Lib\site-packages\aiohttp\connector.py", line 1270, in _create_direct_connection
    raise ClientConnectorError(req.connection_key, exc) from exc
aiohttp.client_exceptions.ClientConnectorError: Cannot connect to host gateway-us-east1-d.discord.gg:443 ssl:default [getaddrinfo failed]
2024-11-30 14:50:24,953 [INFO] Shard ID None has successfully RESUMED session 385c5942a04fb32c1e5874aab8750ecc.
